Workbook

Sheet All Epitope Lists
A1: EPITOPE | B1: EPITOPE_CLEAN | C1: PROTEIN | D1: HXB2 START | E1: HXB2 END | F1: SUBPROTEIN | G1: HXB2 DNA CONTIG | H1: SUBTYPE | I1: SPECIES | J1: HLA | K1: HXB2_GENOME_START | L1: HXB2_GENOME_END | M1: HLA_EPITOPE | N1: ORIGINAL_NAME | O1: Note | P1: Fernando_Approved_Name | Q1: CLADEB_GENOME_START | R1: CLADEB_GENOME_END | S1: NEW_EPITOPE | T1: REF_EPITOPE | U1: DIST_CLEAN_NEW | V1: DIST_CLEAN_REF | W1: DIST_REF_NEW | X1: MATCH (REF&CLEAN)
A2: GELDRWEKI | B2: GELDRWEKI | C2: Gag | D2: 11 | E2: 19 | F2: p17(11-19) | G2: 820..846 | I2: human | J2: B*4002 | K2: 820 | L2: 846 | M2: B4002_Gag_GI9 | N2: #N/A | O2: original name should be B40_Gag_GI9 | P2: B4002_Gag_GI9 | Q2: 42 | R2: 68 | S2: GELDKWEKI | T2: GELDRWEKI | U2: 1 | V2: 0 | W2: 1 | X2: TRUE
A3: DRWEKIRLRPG | B3: DRWEKIRLRPG | C3: Gag | G3: 829..861 | I3: human | J3: B*40 | K3: 829 | L3: 861 | M3: B40_Gag_DG11 | N3: B40_Gag_DG11 | O3: Additional_Epitopes_20240410_CladeB | P3: B40_Gag_DG11 | Q3: 51 | R3: 83 | S3: DKWEKIRLRPG | T3: DRWEKIRLRPG | W3: 1 | X3: TRUE
A4: KIRLRPGGK | B4: KIRLRPGGK | C4: Gag | D4: 18 | E4: 26 | F4: p17(18-26) | G4: 841..867 | I4: human | J4: A*0301 | K4: 841 | L4: 867 | M4: A0301_Gag_KK9 | N4: A03_Gag_KK9 | O4: original name should be A03_Gag_KK9 | P4: A0301_Gag_KK9 | Q4: 63 | R4: 89 | S4: KIRLRPGGK | T4: KIRLRPGGK | U4: 0 | V4: 0 | W4: 0 | X4: TRUE
A5: IRLRPGGKK | B5: IRLRPGGKK | C5: Gag | D5: 19 | E5: 27 | F5: p17(19-27) | G5: 844..870 | H5: B | I5: human | J5: B*2705 | K5: 844 | L5: 870 | M5: B2705_Gag_IK9 | N5: B27_Gag_IK9 | O5: original name should be B27_Gag_IK9 | P5: B2705_Gag_IK9 | Q5: 66 | R5: 92 | S5: IRLRPGGKK | T5: IRLRPGGKK | U5: 0 | V5: 0 | W5: 0 | X5: TRUE
A6: RLRPGGKKK | B6: RLRPGGKKK | C6: Gag | D6: 20 | E6: 28 | F6: p17(20-28) | G6: 847..873 | I6: human | J6: A*0301 | K6: 847 | L6: 873 | M6: A0301_Gag_RK9 | N6: A03_Gag_RK9 | O6: original name should be A03_Gag_RK9 | P6: A0301_Gag_RK9 | Q6: 69 | R6: 95 | S6: RLRPGGKKK | T6: RLRPGGKKK | U6: 0 | V6: 0 | W6: 0 | X6: TRUE
A7: RLRPGGKKKY | B7: RLRPGGKKKY | C7: Gag | D7: 20 | E7: 29 | F7: p17(20-29) | G7: 847..876 | H7: B | I7: human | J7: A*0301 | K7: 847 | L7: 876 | M7: A0301_Gag_RY10 | N7: A03_Gag_RY10 | O7: original name should be A03_Gag_RY10 | P7: A0301_Gag_RY10 | Q7: 69 | R7: 98 | S7: RLRPGGKKKY | T7: RLRPGGKKKY | U7: 0 | V7: 0 | W7: 0 | X7: TRUE
A8: RPGGKKHYM | B8: RPGGKKHYM | C8: Gag | G8: 853..879 | I8: human | J8: B*0702 | K8: 853 | L8: 879 | M8: B0702_Gag_RM9 | N8: B0702_Gag_RM9 | O8: Additional_Epitopes_20240410_CladeB | P8: B0702_Gag_RK9 | Q8: 75 | R8: 101 | S8: RPGGKKHYM | T8: RPGGKKHYM | W8: 0 | X8: TRUE
A9: RPGGKKKYKL | B9: RPGGKKKYKL | C9: Gag | D9: 22 | E9: 31 | F9: p17(22-31) | G9: 853..882 | H9: B | I9: human | J9: B*5101, B*5108 | K9: 853 | L9: 882 | M9: B5101_Gag_RL10 | N9: B51_Gag_RL10 | O9: FINE | P9: B5101_Gag_RL10 | Q9: 75 | R9: 104 | S9: RPGGKKKYKL | T9: RPGGKKKYKL | U9: 0 | V9: 0 | W9: 0 | X9: TRUE
A10: GGKKKYKL | B10: GGKKKYKL | C10: Gag | D10: 24 | E10: 31 | F10: p17(24-31) | G10: 859..882 | H10: B | I10: human | J10: B*0801 | K10: 859 | L10: 882 | M10: B0801_Gag_GL8 | N10: #N/A | O10: original name should be B08_Gag_GL8 | P10: B0801_Gag_GL8 | Q10: 81 | R10: 104 | S10: GGKKKYKL | T10: GGKKKYKL | U10: 0 | V10: 0 | W10: 0 | X10: TRUE
A11: GGKKKYKLK | B11: GGKKKYKLK | C11: Gag | D11: 24 | E11: 32 | F11: p17(24-32) | G11: 859..885 | H11: B | I11: human | J11: B*0801 | K11: 859 | L11: 885 | M11: B0801_Gag_GK9 | N11: B08_Gag_GK9 | O11: original name should be B08_Gag_GK9 | P11: B0801_Gag_GK9 | Q11: 81 | R11: 107 | S11: GGKKKYKLK | T11: GGKKKYKLK | U11: 0 | V11: 0 | W11: 0 | X11: TRUE
A12: KYKLKHIVW | B12: KYKLKHIVW | C12: Gag | D12: 28 | E12: 36 | F12: p17(28-36) | G12: 871..897 | H12: B | I12: human | J12: A*2402, A*2403 | K12: 871 | L12: 897 | M12: A2402_Gag_KW9 | N12: A24_Gag_KW9 | O12: original name should be A24_Gag_KW9 | P12: A2402_Gag_KW9 | Q12: 93 | R12: 119 | S12: KYKLKHIVW | T12: KYKLKHIVW | U12: 0 | V12: 0 | W12: 0 | X12: TRUE
A13: HLVWASREL | B13: HLVWASREL | C13: Gag | D13: 33 | E13: 41 | F13: p17(33-41) | G13: 886..912 | I13: human | J13: Cw*0804, Cw*0802 | K13: 886 | L13: 912 | M13: Cw0804_Gag_HL9 | N13: Cw08_Gag_HL9 | O13: original name should be Cw08_Gag_HL9 | P13: Cw0804_Gag_HL9 | Q13: 108 | R13: 134 | S13: HIVWASREL | T13: HIVWASREL | U13: 1 | V13: 1 | W13: 0 | X13: FALSE
A14: LVWASRELERF | B14: LVWASRELERF | C14: Gag | D14: 34 | E14: 44 | F14: p17(34-44) | G14: 889..921 | I14: human | J14: A*30, A*3001 | K14: 889 | L14: 921 | M14: A30_Gag_LF11 | N14: A30_Gag_LF11 | O14: original name should be A30_Gag_LF11 | P14: A30_Gag_LF11 | Q14: 111 | R14: 143 | S14: IVWASRELERF | T14: IVWASRELERF | U14: 1 | V14: 1 | W14: 0 | X14: FALSE
A15: WASRELERF | B15: WASRELERF | C15: Gag | D15: 36 | E15: 44 | F15: p17(36-44) | G15: 895..921 | H15: B | I15: human | J15: B*3501 | K15: 895 | L15: 921 | M15: B3501_Gag_WF9 | N15: B35_Gag_WF9 | O15: original name should be B35_Gag_WF9 | P15: B3501_Gag_WF9 | Q15: 117 | R15: 143 | S15: WASRELERF | T15: WASRELERF | U15: 0 | V15: 0 | W15: 0 | X15: TRUE
A16: LETSEGCRQI | B16: LETSEGCRQI | C16: Gag | D16: 51 | E16: 60 | G16: 940..969 | I16: human | J16: B*40 | K16: 940 | L16: 969 | M16: B40_Gag_LI10 | N16: B40_Gag_LI10 | O16: Additional_Epitopes_20240410_CladeB | P16: B40_Gag_LI10 | Q16: 162 | R16: 191 | S16: LETSEGCRQI | T16: LETSEGCRQI | W16: 0 | X16: TRUE
A17: GSEELRSLY* | B17: GSEELRSLY | C17: Gag | D17: 71 | E17: 79 | F17: p17(71-79) | G17: 1000..1026 | I17: human | J17: A*0101 | K17: 1000 | L17: 1026 | M17: A0101_Gag_GY9 | N17: A01_Gag_GY9 | O17: original name should be A01_Gag_GY9 | P17: A0101_Gag_GY9 | Q17: 222 | R17: 248 | S17: GSEELRSLY | T17: GSEELRSLY | U17: 0 | V17: 0 | W17: 0 | X17: TRUE
A18: ELRSLYNTV | B18: ELRSLYNTV | C18: Gag | D18: 74 | E18: 82 | F18: p17(74-82) | G18: 1009..1035 | I18: human | J18: B*0801 | K18: 1009 | L18: 1035 | M18: B0801_Gag_EV9 | N18: B08_Gag_EV9 | O18: original name should be B08_Gag_EV9 | P18: B0801_Gag_EV9 | Q18: 231 | R18: 257 | S18: ELRSLYNTV | T18: ELRSLYNTV | U18: 0 | V18: 0 | W18: 0 | X18: TRUE
A19: RSLYNTVATLY | B19: RSLYNTVATLY | C19: Gag | D19: 76 | E19: 86 | F19: p17(76-86) | G19: 1015..1047 | H19: B | I19: human | J19: A*3002, B*58, B*63 | K19: 1015 | L19: 1047 | M19: A3002_Gag_RY11 | N19: A30_Gag_RY11 | O19: original name should be A30_Gag_RY11 | P19: A3002_Gag_RY11 | Q19: 237 | R19: 269 | S19: RSLYNTVATLY | T19: RSLYNTVATLY | U19: 0 | V19: 0 | W19: 0 | X19: TRUE
A20: RSLYNTVATLY | B20: RSLYNTVATLY | C20: Gag | D20: 76 | E20: 86 | G20: 1015..1047 | I20: human | J20: B*58 | K20: 1015 | L20: 1047 | M20: B58_Gag_RY11 | N20: B58_Gag_RY11 | O20: Additional_Epitopes_20240410_CladeB | P20: B58_Gag_RY11 | Q20: 237 | R20: 269 | S20: RSLYNTVATLY | T20: RSLYNTVATLY | U20: 0 | V20: 0 | W20: 0 | X20: TRUE
A21: RSLYNTVATLY | B21: RSLYNTVATLY | C21: Gag | D21: 76 | E21: 86 | F21: p17(76-86) | G21: 1015..1047 | H21: B | I21: human | J21: B*63 | K21: 1015 | L21: 1047 | M21: A63_Gag_RY11 | N21: #N/A | O21: original name should be A63_Gag_RY11 | P21: B63_Gag_RY11 | Q21: 237 | R21: 269 | S21: RSLYNTVATLY | T21: RSLYNTVATLY | U21: 0 | V21: 0 | W21: 0 | X21: TRUE
A22: SLYNTVATL | B22: SLYNTVATL | C22: Gag | D22: 77 | E22: 85 | F22: p17(77-85) | G22: 1018..1044 | H22: B | I22: human | J22: A*0201, A*0202, A*0205 | K22: 1018 | L22: 1044 | M22: A0201_Gag_SL9 | N22: A02_Gag_SL9 | O22: original name should be A02_Gag_SL9 | P22: A0201_Gag_SL9 | Q22: 240 | R22: 266 | S22: SLYNTVATL | T22: SLYNTVATL | U22: 0 | V22: 0 | W22: 0 | X22: TRUE
A23: SLYNTVATLY | B23: SLYNTVATLY | C23: Gag | D23: 77 | E23: 86 | F23: p17(77-86) | G23: 1018..1047 | H23: B | I23: human | J23: A*0201 | K23: 1018 | L23: 1047 | M23: A0201_Gag_SY10 | N23: A02_Gag_SY10 | O23: original name should be A02_Gag_SY10 | P23: A0201_Gag_SY10 | Q23: 240 | R23: 269 | S23: SLYNTVATLY | T23: SLYNTVATLY | U23: 0 | V23: 0 | W23: 0 | X23: TRUE
A24: LYNTVATL | B24: LYNTVATL | C24: Gag | D24: 78 | E24: 85 | F24: p17(78-85) | G24: 1021..1044 | I24: human | J24: Cw*14 | K24: 1021 | L24: 1044 | M24: Cw14_Gag_LL8 | N24: Cw14_Gag_LL8 | O24: original name should be Cw14_Gag_LL8 | P24: Cw14_Gag_LL8 | Q24: 243 | R24: 266 | S24: LYNTVATL | T24: LYNTVATL | U24: 0 | V24: 0 | W24: 0 | X24: TRUE
A25: LYNTVATLY | B25: LYNTVATLY | C25: Gag | D25: 78 | E25: 86 | F25: p17(78-86) | G25: 1021..1047 | I25: human | J25: A*2902, B*4403 | K25: 1021 | L25: 1047 | M25: A2902_Gag_LY9 | N25: A29_Gag_LY9 | O25: original name should be A29_Gag_LY9 | P25: A2902_Gag_LY9 | Q25: 243 | R25: 269 | S25: LYNTVATLY | T25: LYNTVATLY | U25: 0 | V25: 0 | W25: 0 | X25: TRUE
A26: LYNTVATLY | B26: LYNTVATLY | C26: Gag | D26: 78 | E26: 86 | G26: 1021..1047 | I26: human | J26: B*4403 | K26: 1021 | L26: 1047 | M26: B44_Gag_LY9 | N26: B44_Gag_LY9 | O26: Additional_Epitopes_20240410_CladeB | P26: B4403_Gag_LY9 | Q26: 243 | R26: 269 | S26: LYNTVATLY | T26: LYNTVATLY | U26: 0 | V26: 0 | W26: 0 | X26: TRUE
A27: TLYCVHQK | B27: TLYCVHQK | C27: Gag | D27: 84 | E27: 91 | F27: p17(84-91) | G27: 1039..1062 | I27: human | J27: A*1101 | K27: 1039 | L27: 1062 | M27: A1101_Gag_TK8 | N27: A11_Gag_TI9 | O27: original name should be A11_Gag_TK8 | P27: A1101_Gag_TK8 | Q27: 261 | R27: 284 | S27: TLYCVHQK | T27: TLYCVHQR | U27: 0 | V27: 1 | W27: 1 | X27: FALSE
A28: IEIKDTKEAL | B28: IEIKDTKEAL | C28: Gag | D28: 92 | E28: 101 | F28: p17(92-101) | G28: 1063..1092 | I28: human | J28: B*4001 | K28: 1063 | L28: 1092 | M28: B4001_Gag_IL10 | N28: B4001_Gag_IL10 | O28: FINE | P28: B4001_Gag_IL10 | Q28: 285 | R28: 314 | S28: IEVKDTKEAL | T28: IEIKDTKEAL | U28: 1 | V28: 0 | W28: 1 | X28: TRUE
A29: NSSKVSQNY | B29: NSSKVSQNY | C29: Gag | D29: 124 | E29: 132 | F29: p17(124-132) | G29: 1159..1185 | H29: B | I29: human | J29: B*3501 | K29: 1159 | L29: 1185 | M29: B3501_Gag_NY9 | N29: B35_Gag_NNY9 | O29: original name should be B35_Gag_NY9 | P29: B3501_Gag_NY9 | Q29: 381 | R29: 407 | S29: NSSQVSQNY | T29: HSNQVSQNY | U29: 1 | V29: 3 | W29: 2 | X29: FALSE
A30: VQNLQGQMV | B30: VQNLQGQMV | C30: Gag | D30: 135 | E30: 143 | F30: p24(3-11) | G30: 1192..1218 | I30: human | J30: B*13 | K30: 1192 | L30: 1218 | M30: B13_Gag_VV9 | N30: B13_Gag_VV9 | O30: original name should be B13_Gag_VV9 | P30: B13_Gag_VV9 | Q30: 414 | R30: 440 | S30: VQNLQGQMV | T30: VQNIQGQMV | U30: 0 | V30: 1 | W30: 1 | X30: FALSE
A31: GQMVHQAI | B31: GQMVHQAI | C31: Gag | D31: 140 | E31: 147 | G31: 1207..1230 | I31: human | J31: B*1302 | K31: 1207 | L31: 1230 | M31: B1302_Gag_GI8 | N31: B1302_Gag_GI8 | O31: Additional_Epitopes_20240410_CladeB | P31: B1302_Gag_GI8 | Q31: 429 | R31: 452 | S31: GQMVHQAI | T31: GQMVHQAI | W31: 0 | X31: TRUE
A32: HQAISPRTL | B32: HQAISPRTL | C32: Gag | D32: 144 | E32: 152 | F32: p24(12-20) | G32: 1219..1245 | I32: human | J32: B*1510 | K32: 1219 | L32: 1245 | M32: B1510_Gag_HL9 | N32: B1510_Gag_HL9 | O32: original name should be B15_Gag_HL9 | P32: B1510_Gag_HL9 | Q32: 441 | R32: 467 | S32: HQAISPRTL | T32: HQAISPRTL | U32: 0 | V32: 0 | W32: 0 | X32: TRUE
A33: QAISPRTLNAW | B33: QAISPRTLNAW | C33: Gag | D33: 145 | E33: 155 | F33: p24(13-23) | G33: 1222..1254 | H33: B | I33: human | J33: A*2501 | K33: 1222 | L33: 1254 | M33: A2501_Gag_QW11 | N33: A25_Gag_QW11 | O33: original name should be A25_Gag_QW11 | P33: A2501_Gag_QW11 | Q33: 444 | R33: 476 | S33: QAISPRTLNAW | T33: QAISPRTLNAW | U33: 0 | V33: 0 | W33: 0 | X33: TRUE
A34: ISPRTLNAW | B34: ISPRTLNAW | C34: Gag | D34: 147 | E34: 155 | F34: p24(15-23) | G34: 1228..1254 | I34: human | J34: B*5701, B*63, B*5703 | K34: 1228 | L34: 1254 | M34: B5701_Gag_IW9 | N34: #N/A | O34: original name should be B57_Gag_IW9 | P34: B5701_Gag_IW9 | Q34: 450 | R34: 476 | S34: ISPRTLNAW | T34: ISPRTLNAW | U34: 0 | V34: 0 | W34: 0 | X34: TRUE
A35: ISPRTLNAW | B35: ISPRTLNAW | C35: Gag | D35: 147 | E35: 155 | G35: 1228..1254 | I35: human | J35: B*63 | K35: 1228 | L35: 1254 | M35: B63_Gag_IW9 | N35: #N/A | O35: original name should be B63_Gag_IW9 | P35: B63_Gag_IW9 | Q35: 450 | R35: 476 | S35: ISPRTLNAW | T35: ISPRTLNAW | U35: 0 | V35: 0 | W35: 0 | X35: TRUE
A36: SPRTLNAWV | B36: SPRTLNAWV | C36: Gag | D36: 148 | E36: 156 | F36: p24(16-24) | G36: 1231..1257 | I36: human | J36: B*0702 | K36: 1231 | L36: 1257 | M36: B0702_Gag_SV9 | N36: B07_Gag_SV9 | O36: original name should be B07_Gag_SV9 | P36: B0702_Gag_SV9 | Q36: 453 | R36: 479 | S36: SPRTLNAWV | T36: SPRTLNAWV | U36: 0 | V36: 0 | W36: 0 | X36: TRUE
A37: VKVIEEKAF | B37: VKVIEEKAF | C37: Gag | D37: 156 | E37: 164 | F37: p24(24-32) | G37: 1255..1281 | I37: human | J37: B*1503 | K37: 1255 | L37: 1281 | M37: B1503_Gag_VF9 | N37: B1503_Gag_VF9 | O37: original name should be B15_Gag_VF9 | P37: B1503_Gag_VF9 | Q37: 477 | R37: 503 | S37: VKVVEEKAF | T37: VKVVEEKAF | U37: 1 | V37: 1 | W37: 0 | X37: FALSE
A38: EEKAFSPEV | B38: EEKAFSPEV | C38: Gag | D38: 160 | E38: 168 | F38: p24(28-36) | G38: 1267..1293 | I38: human | J38: B*4415 | K38: 1267 | L38: 1293 | M38: B4415_Gag_EV9 | N38: B44_Gag_EV9 | O38: original name should be B44_Gag_EV9 | P38: B4415_Gag_EV9 | Q38: 489 | R38: 515 | S38: EEKAFSPEV | T38: EEKAFSPEV | U38: 0 | V38: 0 | W38: 0 | X38: TRUE
A39: KAFSPEVI | B39: KAFSPEVI | C39: Gag | D39: 162 | E39: 169 | F39: p24(30-37) | G39: 1273..1296 | H39: B | I39: human | J39: B*5701, B*5703 | K39: 1273 | L39: 1296 | M39: B5703_Gag_KI8 | N39: B57_Gag_KI8 | O39: original name should be B57_Gag_KI8 | P39: B5703_Gag_KI8 | Q39: 495 | R39: 518 | S39: KAFSPEVI | T39: KAFSPEVI | U39: 0 | V39: 0 | W39: 0 | X39: TRUE
A40: KAFSPEVIPMF | B40: KAFSPEVIPMF | C40: Gag | D40: 162 | E40: 172 | F40: p24(30-40) | G40: 1273..1305 | H40: B | I40: human | J40: B*5701, B*5703, B*63 | K40: 1273 | L40: 1305 | M40: B5701_Gag_KF11 | N40: B57_Gag_KF11 | O40: original name should be B57_Gag_KF11 | P40: B5701_Gag_KF11 | Q40: 495 | R40: 527 | S40: KAFSPEVIPMF | T40: KAFSPEVIPMF | U40: 0 | V40: 0 | W40: 0 | X40: TRUE
...

Sheet ASublist_HXB2_20240606
A1: ='All Epitope Lists'!$P2 -> B4002_Gag_GI9 | B1: ='All Epitope Lists'!$K2 -> 820 | C1: ='All Epitope Lists'!$L2 -> 846
A2: ='All Epitope Lists'!$P3 -> B40_Gag_DG11 | B2: ='All Epitope Lists'!$K3 -> 829 | C2: ='All Epitope Lists'!$L3 -> 861
A3: ='All Epitope Lists'!$P4 -> A0301_Gag_KK9 | B3: ='All Epitope Lists'!$K4 -> 841 | C3: ='All Epitope Lists'!$L4 -> 867
A4: ='All Epitope Lists'!$P5 -> B2705_Gag_IK9 | B4: ='All Epitope Lists'!$K5 -> 844 | C4: ='All Epitope Lists'!$L5 -> 870
A5: ='All Epitope Lists'!$P6 -> A0301_Gag_RK9 | B5: ='All Epitope Lists'!$K6 -> 847 | C5: ='All Epitope Lists'!$L6 -> 873
A6: ='All Epitope Lists'!$P7 -> A0301_Gag_RY10 | B6: ='All Epitope Lists'!$K7 -> 847 | C6: ='All Epitope Lists'!$L7 -> 876
A7: ='All Epitope Lists'!$P8 -> B0702_Gag_RK9 | B7: ='All Epitope Lists'!$K8 -> 853 | C7: ='All Epitope Lists'!$L8 -> 879
A8: ='All Epitope Lists'!$P9 -> B5101_Gag_RL10 | B8: ='All Epitope Lists'!$K9 -> 853 | C8: ='All Epitope Lists'!$L9 -> 882
A9: ='All Epitope Lists'!$P10 -> B0801_Gag_GL8 | B9: ='All Epitope Lists'!$K10 -> 859 | C9: ='All Epitope Lists'!$L10 -> 882
A10: ='All Epitope Lists'!$P11 -> B0801_Gag_GK9 | B10: ='All Epitope Lists'!$K11 -> 859 | C10: ='All Epitope Lists'!$L11 -> 885
A11: ='All Epitope Lists'!$P12 -> A2402_Gag_KW9 | B11: ='All Epitope Lists'!$K12 -> 871 | C11: ='All Epitope Lists'!$L12 -> 897
A12: ='All Epitope Lists'!$P13 -> Cw0804_Gag_HL9 | B12: ='All Epitope Lists'!$K13 -> 886 | C12: ='All Epitope Lists'!$L13 -> 912
... A142: ='All Epitope Lists'!$P143 -> A0201_Pol_VV11 | B142: ='All Epitope Lists'!$K143 -> 3084 | C142: ='All Epitope Lists'!$L143 -> 3116
A143: ='All Epitope Lists'!$P145 -> B4001_Pol_IL9 | B143: ='All Epitope Lists'!$K145 -> 3153 | C143: ='All Epitope Lists'!$L145 -> 3179
A144: ='All Epitope Lists'!$P146 -> B5701_Pol_IW9 | B144: ='All Epitope Lists'!$K146 -> 3279 | C144: ='All Epitope Lists'!$L146 -> 3305
A145: ='All Epitope Lists'!$P147 -> B1501_Pol_LY12 | B145: ='All Epitope Lists'!$K147 -> 3327 | C145: ='All Epitope Lists'!$L147 -> 3362
A146: ='All Epitope Lists'!$P148 -> A3002_Pol_KIY9 | B146: ='All Epitope Lists'!$K148 -> 3336 | C146: ='All Epitope Lists'!$L148 -> 3362
A147: ='All Epitope Lists'!$P149 -> A0301_Pol_QR9 | B147: ='All Epitope Lists'!$K149 -> 3354 | C147: ='All Epitope Lists'!$L149 -> 3380
A148: ='All Epitope Lists'!$P150 -> B4201_Pol_YL9 | B148: ='All Epitope Lists'!$K150 -> 3360 | C148: ='All Epitope Lists'!$L150 -> 3386
A149: ='All Epitope Lists'!$P151 -> B3501_Pol_IL9 | B149: ='All Epitope Lists'!$K151 -> 3426 | C149: ='All Epitope Lists'!$L151 -> 3452
A150: ='All Epitope Lists'!$P152 -> B5101_Pol_IL9 | B150: ='All Epitope Lists'!$K152 -> 3426 | C150: ='All Epitope Lists'!$L152 -> 3452
A151: ='All Epitope Lists'!$P153 -> A0201_Pol_IV9 | B151: ='All Epitope Lists'!$K153 -> 3474 | C151: ='All Epitope Lists'!$L153 -> 3500
A152: ='All Epitope Lists'!$P154 -> B1501_Pol_IY10 | B152: ='All Epitope Lists'!$K154 -> 3474 | C152: ='All Epitope Lists'!$L154 -> 3503
A153: ='All Epitope Lists'!$P155 -> Cw1202_Pol_IY10 | B153: ='All Epitope Lists'!$K155 -> 3474 | C153: ='All Epitope Lists'!$L155 -> 3503
A154: ='All Epitope Lists'!$P156 -> A24_Pol_VL9 | B154: ='All Epitope Lists'!$K156 -> 3498 | C154: ='All Epitope Lists'!$L156 -> 3525
... A223: ='All Epitope Lists'!$P225 -> B53_Tat_EW10 | B223: ='All Epitope Lists'!$K225 -> 5834 | C223: ='All Epitope Lists'!$L225 -> 5863
A224: ='All Epitope Lists'!#REF! -> #REF! | B224: ='All Epitope Lists'!#REF! -> #REF! | C224: ='All Epitope Lists'!#REF! -> #REF!
A225: ='All Epitope Lists'!$P226 -> Cw12_Tat_CC8 | B225: ='All Epitope Lists'!$K226 -> 5918 | C225: ='All Epitope Lists'!$L226 -> 5941
A226: ='All Epitope Lists'!$P227 -> B1503_Tat_FY10 | B226: ='All Epitope Lists'!$K227 -> 5942 | C226: ='All Epitope Lists'!$L227 -> 5971
A227: ='All Epitope Lists'!$P228 -> A6801_Tat_IR11 | B227: ='All Epitope Lists'!$K228 -> 5945 | C227: ='All Epitope Lists'!$L228 -> 5977
A228: ='All Epitope Lists'!$P229 -> B4402_Rev_EL9 | B228: ='All Epitope Lists'!$K229 -> 5997 | C228: ='All Epitope Lists'!$L229 -> 6023
A229: ='All Epitope Lists'!$P230 -> B5701_Rev_KY10 | B229: ='All Epitope Lists'!$K230 -> 6009 | C229: ='All Epitope Lists'!$L230 -> 6038
A230: ='All Epitope Lists'!$P231 -> B5703_Rev_QY10 | B230: ='All Epitope Lists'!$K231 -> 6009 | C230: ='All Epitope Lists'!$L231 -> 6038
A231: ='All Epitope Lists'!$P232 -> B5801_Rev_KY10 | B231: ='All Epitope Lists'!$K232 -> 6009 | C231: ='All Epitope Lists'!$L232 -> 6038
A232: ='All Epitope Lists'!$P233 -> B63_Rev_KY10 | B232: ='All Epitope Lists'!$K233 -> 6009 | C232: ='All Epitope Lists'!$L233 -> 6038
A233: ='All Epitope Lists'!$P234 -> Cw18_Vpu_YI9 | B233: ='All Epitope Lists'!$K234 -> 6074 | C233: ='All Epitope Lists'!$L234 -> 6100
A234: ='All Epitope Lists'!$P235 -> A3303_Vpu_ER9 | B234: ='All Epitope Lists'!$K235 -> 6146 | C234: ='All Epitope Lists'!$L235 -> 6172
A235: ='All Epitope Lists'!$P236 -> B0801_gp160_RL9 | B235: ='All Epitope Lists'!$K236 -> 6228 | C235: ='All Epitope Lists'!$L236 -> 6254
A236: ='All Epitope Lists'!$P237 -> B1801_gp160_AY9 | B236: ='All Epitope Lists'!$K237 -> 6315 | C236: ='All Epitope Lists'!$L237 -> 6341
... A311: ='All Epitope Lists'!$P312 -> A0205_Nef_GL9 | B311: ='All Epitope Lists'!$K312 -> 9043 | C311: ='All Epitope Lists'!$L312 -> 9069
...

Sheet ASublist_CladeB_20240606
A1: ='All Epitope Lists'!$P2 -> B4002_Gag_GI9 | B1: ='All Epitope Lists'!$Q2 -> 42 | C1: ='All Epitope Lists'!$R2 -> 68
A2: ='All Epitope Lists'!$P3 -> B40_Gag_DG11 | B2: ='All Epitope Lists'!$Q3 -> 51 | C2: ='All Epitope Lists'!$R3 -> 83
A3: ='All Epitope Lists'!$P4 -> A0301_Gag_KK9 | B3: ='All Epitope Lists'!$Q4 -> 63 | C3: ='All Epitope Lists'!$R4 -> 89
A4: ='All Epitope Lists'!$P5 -> B2705_Gag_IK9 | B4: ='All Epitope Lists'!$Q5 -> 66 | C4: ='All Epitope Lists'!$R5 -> 92
A5: ='All Epitope Lists'!$P6 -> A0301_Gag_RK9 | B5: ='All Epitope Lists'!$Q6 -> 69 | C5: ='All Epitope Lists'!$R6 -> 95
A6: ='All Epitope Lists'!$P7 -> A0301_Gag_RY10 | B6: ='All Epitope Lists'!$Q7 -> 69 | C6: ='All Epitope Lists'!$R7 -> 98
A7: ='All Epitope Lists'!$P8 -> B0702_Gag_RK9 | B7: ='All Epitope Lists'!$Q8 -> 75 | C7: ='All Epitope Lists'!$R8 -> 101
A8: ='All Epitope Lists'!$P9 -> B5101_Gag_RL10 | B8: ='All Epitope Lists'!$Q9 -> 75 | C8: ='All Epitope Lists'!$R9 -> 104
A9: ='All Epitope Lists'!$P10 -> B0801_Gag_GL8 | B9: ='All Epitope Lists'!$Q10 -> 81 | C9: ='All Epitope Lists'!$R10 -> 104
A10: ='All Epitope Lists'!$P11 -> B0801_Gag_GK9 | B10: ='All Epitope Lists'!$Q11 -> 81 | C10: ='All Epitope Lists'!$R11 -> 107
A11: ='All Epitope Lists'!$P12 -> A2402_Gag_KW9 | B11: ='All Epitope Lists'!$Q12 -> 93 | C11: ='All Epitope Lists'!$R12 -> 119
A12: ='All Epitope Lists'!$P13 -> Cw0804_Gag_HL9 | B12: ='All Epitope Lists'!$Q13 -> 108 | C12: ='All Epitope Lists'!$R13 -> 134
... A142: ='All Epitope Lists'!$P143 -> A0201_Pol_VV11 | B142: ='All Epitope Lists'!$Q143 -> 2306 | C142: ='All Epitope Lists'!$R143 -> 2338
A143: ='All Epitope Lists'!$P145 -> B4001_Pol_IL9 | B143: ='All Epitope Lists'!$Q145 -> 2375 | C143: ='All Epitope Lists'!$R145 -> 2401
A144: ='All Epitope Lists'!$P146 -> B5701_Pol_IW9 | B144: ='All Epitope Lists'!$Q146 -> 2501 | C144: ='All Epitope Lists'!$R146 -> 2527
A145: ='All Epitope Lists'!$P147 -> B1501_Pol_LY12 | B145: ='All Epitope Lists'!$Q147 -> 2549 | C145: ='All Epitope Lists'!$R147 -> 2584
A146: ='All Epitope Lists'!$P148 -> A3002_Pol_KIY9 | B146: ='All Epitope Lists'!$Q148 -> 2558 | C146: ='All Epitope Lists'!$R148 -> 2584
A147: ='All Epitope Lists'!$P149 -> A0301_Pol_QR9 | B147: ='All Epitope Lists'!$Q149 -> 2576 | C147: ='All Epitope Lists'!$R149 -> 2602
A148: ='All Epitope Lists'!$P150 -> B4201_Pol_YL9 | B148: ='All Epitope Lists'!$Q150 -> 2582 | C148: ='All Epitope Lists'!$R150 -> 2608
A149: ='All Epitope Lists'!$P151 -> B3501_Pol_IL9 | B149: ='All Epitope Lists'!$Q151 -> 2648 | C149: ='All Epitope Lists'!$R151 -> 2674
A150: ='All Epitope Lists'!$P152 -> B5101_Pol_IL9 | B150: ='All Epitope Lists'!$Q152 -> 2648 | C150: ='All Epitope Lists'!$R152 -> 2674
A151: ='All Epitope Lists'!$P153 -> A0201_Pol_IV9 | B151: ='All Epitope Lists'!$Q153 -> 2696 | C151: ='All Epitope Lists'!$R153 -> 2722
A152: ='All Epitope Lists'!$P154 -> B1501_Pol_IY10 | B152: ='All Epitope Lists'!$Q154 -> 2696 | C152: ='All Epitope Lists'!$R154 -> 2725
A153: ='All Epitope Lists'!$P155 -> Cw1202_Pol_IY10 | B153: ='All Epitope Lists'!$Q155 -> 2696 | C153: ='All Epitope Lists'!$R155 -> 2725
A154: ='All Epitope Lists'!$P156 -> A24_Pol_VL9 | B154: ='All Epitope Lists'!$Q156 -> 2720 | C154: ='All Epitope Lists'!$R156 -> 2747
... A223: ='All Epitope Lists'!$P225 -> B53_Tat_EW10 | B223: ='All Epitope Lists'!$Q225 -> 5055 | C223: ='All Epitope Lists'!$R225 -> 5084
A224: ='All Epitope Lists'!#REF! -> #REF! | B224: ='All Epitope Lists'!#REF! -> #REF! | C224: ='All Epitope Lists'!#REF! -> #REF!
A225: ='All Epitope Lists'!$P226 -> Cw12_Tat_CC8 | B225: ='All Epitope Lists'!$Q226 -> 5139 | C225: ='All Epitope Lists'!$R226 -> 5162
A226: ='All Epitope Lists'!$P227 -> B1503_Tat_FY10 | B226: ='All Epitope Lists'!$Q227 -> 5163 | C226: ='All Epitope Lists'!$R227 -> 5192
A227: ='All Epitope Lists'!$P228 -> A6801_Tat_IR11 | B227: ='All Epitope Lists'!$Q228 -> 5166 | C227: ='All Epitope Lists'!$R228 -> 5198
A228: ='All Epitope Lists'!$P229 -> B4402_Rev_EL9 | B228: ='All Epitope Lists'!$Q229 -> 5218 | C228: ='All Epitope Lists'!$R229 -> 5244
A229: ='All Epitope Lists'!$P230 -> B5701_Rev_KY10 | B229: ='All Epitope Lists'!$Q230 -> 5230 | C229: ='All Epitope Lists'!$R230 -> 5259
A230: ='All Epitope Lists'!$P231 -> B5703_Rev_QY10 | B230: ='All Epitope Lists'!$Q231 -> 5230 | C230: ='All Epitope Lists'!$R231 -> 5259
A231: ='All Epitope Lists'!$P232 -> B5801_Rev_KY10 | B231: ='All Epitope Lists'!$Q232 -> 5230 | C231: ='All Epitope Lists'!$R232 -> 5259
A232: ='All Epitope Lists'!$P233 -> B63_Rev_KY10 | B232: ='All Epitope Lists'!$Q233 -> 5230 | C232: ='All Epitope Lists'!$R233 -> 5259
A233: ='All Epitope Lists'!$P234 -> Cw18_Vpu_YI9 | B233: ='All Epitope Lists'!$Q234 -> 5295 | C233: ='All Epitope Lists'!$R234 -> 5321
A234: ='All Epitope Lists'!$P235 -> A3303_Vpu_ER9 | B234: ='All Epitope Lists'!$Q235 -> 5367 | C234: ='All Epitope Lists'!$R235 -> 5393
A235: ='All Epitope Lists'!$P236 -> B0801_gp160_RL9 | B235: ='All Epitope Lists'!$Q236 -> 5458 | C235: ='All Epitope Lists'!$R236 -> 5484
A236: ='All Epitope Lists'!$P237 -> B1801_gp160_AY9 | B236: ='All Epitope Lists'!$Q237 -> 5533 | C236: ='All Epitope Lists'!$R237 -> 5559
... A311: ='All Epitope Lists'!$P312 -> A0205_Nef_GL9 | B311: ='All Epitope Lists'!$Q312 -> 8249 | C311: ='All Epitope Lists'!$R312 -> 8275
...
